<?xml version="1.0" ?>
<!-- =================================================================================== -->
<!-- |    This document was autogenerated by xacro from car.xacro                      | -->
<!-- |    EDITING THIS FILE BY HAND IS NOT RECOMMENDED                                 | -->
<!-- =================================================================================== -->
<robot name="rc_car">
  <material name="orange">
    <color rgba="1 .64  0  1"/>
  </material>
  <material name="black">
    <color rgba="1 1 1 1"/>
  </material>
  <!-- Inertial Macro -->
  <!-- Chassis Link Definition -->
  <link name="chassis">
    <visual>
      <origin rpy="0 0 0" xyz="0 0 0.09075"/>
      <geometry>
        <mesh filename="package://rc_car/meshes/Chassis.dae"/>
      </geometry>
      <!--  <material name="orange"/>  Uncomment for Rviz -->
    </visual>
    <collision>
      <origin rpy="0 0 0" xyz="0 0 0.09075"/>
      <geometry>
        <mesh filename="package://rc_car/meshes/Chassis.dae"/>
      </geometry>
    </collision>
    <inertial>
      <mass value="1"/>
      <inertia ixx="0.00414500685" ixy="0.0" ixz="0.0" iyy="0.01911488783" iyz="0.0" izz="0.02164626315"/>
      <origin rpy="0 0 0" xyz="0 0 0.088381"/>
    </inertial>
  </link>
  <gazebo reference="chassis">
    <material>Gazebo/Orange</material>
  </gazebo>
  <!-- Wheel Definition -->
  <!-- Calling Wheel Macro -->
  <link name="front_right_wheel">
    <visual>
      <geometry>
        <mesh filename="package://rc_car/meshes/Wheel.dae"/>
      </geometry>
      <origin rpy="0 0 1.5707963267948966 " xyz="0 0 0"/>
      <!--  <material name="black"/> Uncomment for Rviz -->
    </visual>
    <collision>
      <geometry>
        <mesh filename="package://rc_car/meshes/Wheel.dae"/>
      </geometry>
      <origin rpy="0 0 1.5707963267948966" xyz="0 0 0"/>
    </collision>
    <inertial>
      <mass value="0.2"/>
      <inertia ixx="0.0002243658" ixy="0.0" ixz="0.0" iyy="0.00041873192200000004" iyz="0.0" izz="0.0002243658"/>
    </inertial>
  </link>
  <joint name="front_right_wheel_to_chassis" type="continuous">
    <axis rpy="0 0 0" xyz="0 1 0"/>
    <parent link="chassis"/>
    <child link="front_right_wheel"/>
    <origin rpy="0 0 0" xyz="0.14 -0.115 0.06075"/>
  </joint>
  <gazebo reference="front_right_wheel">
    <material>Gazebo/Black</material>
  </gazebo>
  <link name="rear_right_wheel">
    <visual>
      <geometry>
        <mesh filename="package://rc_car/meshes/Wheel.dae"/>
      </geometry>
      <origin rpy="0 0 1.5707963267948966 " xyz="0 0 0"/>
      <!--  <material name="black"/> Uncomment for Rviz -->
    </visual>
    <collision>
      <geometry>
        <mesh filename="package://rc_car/meshes/Wheel.dae"/>
      </geometry>
      <origin rpy="0 0 1.5707963267948966" xyz="0 0 0"/>
    </collision>
    <inertial>
      <mass value="0.2"/>
      <inertia ixx="0.0002243658" ixy="0.0" ixz="0.0" iyy="0.00041873192200000004" iyz="0.0" izz="0.0002243658"/>
    </inertial>
  </link>
  <joint name="rear_right_wheel_to_chassis" type="continuous">
    <axis rpy="0 0 0" xyz="0 1 0"/>
    <parent link="chassis"/>
    <child link="rear_right_wheel"/>
    <origin rpy="0 0 0" xyz="-0.14 -0.115 0.06075"/>
  </joint>
  <gazebo reference="rear_right_wheel">
    <material>Gazebo/Black</material>
  </gazebo>
  <link name="front_left_wheel">
    <visual>
      <geometry>
        <mesh filename="package://rc_car/meshes/Wheel.dae"/>
      </geometry>
      <origin rpy="0 0 1.5707963267948966 " xyz="0 0 0"/>
      <!--  <material name="black"/> Uncomment for Rviz -->
    </visual>
    <collision>
      <geometry>
        <mesh filename="package://rc_car/meshes/Wheel.dae"/>
      </geometry>
      <origin rpy="0 0 1.5707963267948966" xyz="0 0 0"/>
    </collision>
    <inertial>
      <mass value="0.2"/>
      <inertia ixx="0.0002243658" ixy="0.0" ixz="0.0" iyy="0.00041873192200000004" iyz="0.0" izz="0.0002243658"/>
    </inertial>
  </link>
  <joint name="front_left_wheel_to_chassis" type="continuous">
    <axis rpy="0 0 0" xyz="0 1 0"/>
    <parent link="chassis"/>
    <child link="front_left_wheel"/>
    <origin rpy="0 0 0" xyz="0.14 0.115 0.06075"/>
  </joint>
  <gazebo reference="front_left_wheel">
    <material>Gazebo/Black</material>
  </gazebo>
  <link name="rear_left_wheel">
    <visual>
      <geometry>
        <mesh filename="package://rc_car/meshes/Wheel.dae"/>
      </geometry>
      <origin rpy="0 0 1.5707963267948966 " xyz="0 0 0"/>
      <!--  <material name="black"/> Uncomment for Rviz -->
    </visual>
    <collision>
      <geometry>
        <mesh filename="package://rc_car/meshes/Wheel.dae"/>
      </geometry>
      <origin rpy="0 0 1.5707963267948966" xyz="0 0 0"/>
    </collision>
    <inertial>
      <mass value="0.2"/>
      <inertia ixx="0.0002243658" ixy="0.0" ixz="0.0" iyy="0.00041873192200000004" iyz="0.0" izz="0.0002243658"/>
    </inertial>
  </link>
  <joint name="rear_left_wheel_to_chassis" type="continuous">
    <axis rpy="0 0 0" xyz="0 1 0"/>
    <parent link="chassis"/>
    <child link="rear_left_wheel"/>
    <origin rpy="0 0 0" xyz="-0.14 0.115 0.06075"/>
  </joint>
  <gazebo reference="rear_left_wheel">
    <material>Gazebo/Black</material>
  </gazebo>
  <!-- Loading differential drive plugin -->
  <gazebo>
    <plugin filename="libgazebo_ros_diff_drive.so" name="differential_drive_controller">
      <leftJoint>rear_left_wheel_to_chassis</leftJoint>
      <rightJoint>rear_right_wheel_to_chassis</rightJoint>
      <robotBaseFrame>chassis</robotBaseFrame>
      <wheelSeparation>0.2</wheelSeparation>
      <wheelDiameter>0.1215</wheelDiameter>
      <commandTopic>cmd_vel</commandTopic>
      <odometryTopic>odom</odometryTopic>
      <odometryFrame>odom</odometryFrame>
      <publishWheelJointState>true</publishWheelJointState>
      <alwaysOn>true</alwaysOn>
      <legacyMode>false</legacyMode>
      <updateRate>40</updateRate>
      <wheelTorque>5</wheelTorque>
      <odometrySource>world</odometrySource>
      <publishWheelTF>true</publishWheelTF>
      <wheelAcceleration>0</wheelAcceleration>
      <rosDebugLevel>na</rosDebugLevel>
      <publishOdomTF>true</publishOdomTF>
    </plugin>
  </gazebo>
</robot>

